Workbook

Sheet Datos Diarios
A1: 45839
A2: CLIENTE | B2: ZONA | C2: 1 | D2: 2 | E2: 3 | F2: 4 | G2: 5 | H2: 6 | I2: 7 | J2: 8 | K2: 9 | L2: 10 | M2: 11 | N2: 12 | O2: 13 | P2: 14 | Q2: 15 | R2: 16 | S2: 17 | T2: 18 | U2: 19 | V2: 20 | W2: 21 | X2: 22 | Y2: 23 | Z2: 24 | AA2: 25 | AB2: 26 | AC2: 27 | AD2: 28 | AE2: 29 | AF2: 30 | AG2: 31 | AH2: Enviados | AI2: Entregados por dia | AJ2: Pedidos Por dia | AK2: % Desvio | AL2: Datos pedidos 1 | AM2: Datos pedidos 2 | AN2: Faltantes a enviar | AO2: CPL | AP2: INVERSION REALIZADA | AQ2: INVERSION PENDIENTE
A3: NOVO GROUP - FIAT | B3: NACIONAL | AJ3: 25 | AL3: 100
A4: RENAULT | B4: AMBA | P4: {=TRANSPOSE(Renault!L2:L32)} -> #REF! | AH4: 19 | AI4: =AVERAGE(C4:AH4) -> #REF! | AJ4: 10 | AK4: =AI4*100/AJ4-100 -> #REF! | AL4: 20 | AN4: =AL4-AH4 -> 1
A5: GRUPO QUIJADA - PEUGEOT | B5: CORDOBA | P5: {=TRANSPOSE(Renault!L22:L39)} | AI5: =AVERAGE(C5:AG5) -> #DIV/0! | AJ5: 20 | AK5: =AI5*100/AJ5-100 -> #DIV/0! | AL5: 100 | AN5: =AL5-AH5 -> 100
A6: GRUPO QUIJADA - CITROEN | B6: AMBA | AI6: =AVERAGE(C6:AG6) -> #DIV/0! | AJ6: 20 | AK6: =AI6*100/AJ6-100 -> #DIV/0! | AL6: 100 | AN6: =AL6-AH6 -> 100
A7: CHEVROLET - ITALY | B7: PAIS | P7: {=TRANSPOSE(Chevrolet!L2:L19)} -> 17 | Q7: 28 | R7: 2 | AH7: =SUM(C7:AG7) -> 47 | AI7: =AVERAGE(C7:AH7) -> 23.5 | AJ7: 10 | AK7: =AI7*100/AJ7-100 -> 135 | AL7: 100 | AN7: =AL7-AH7 -> 53 | AO7: 1377
A8: PEUGEOT ALBENS | B8: PAIS | C8: {=TRANSPOSE(Peugeot!L27:L48)} -> 13 | D8: 34 | E8: 26 | F8: 25 | G8: 17 | H8: 20 | I8: 30 | J8: 28 | K8: 25 | L8: 22 | M8: 13 | N8: 26 | O8: 25 | P8: 19 | Q8: 2 | AH8: =SUM(C8:AG8) -> 325 | AI8: =AVERAGE(C8:AG8) -> 21.666667 | AJ8: 20 | AK8: =AI8*100/AJ8-100 -> 8.3333333 | AL8: 400 | AN8: =AL8-AH8 -> 75 | AO8: 973 | AP8: =AO8*AH8 -> 316225 | AQ8: =AN8*AO8 -> 72975
A9: FIAT AUTOS DEL SOL | B9: AMBA | C9: {=TRANSPOSE(Fiat!L20:L50)} -> 22 | D9: 25 | E9: 32 | F9: 29 | G9: 21 | H9: 39 | I9: 29 | J9: 29 | K9: 19 | L9: 38 | M9: 24 | N9: 29 | O9: 26 | P9: 33 | Q9: 45 | R9: 11 | AH9: =SUM(C9:AG9) -> 451 | AI9: =AVERAGE(C9:AG9) -> 28.1875 | AJ9: 30 | AK9: =AI9*100/AJ9-100 -> -6.0416667 | AL9: 500 | AN9: =AL9-AH9 -> 49 | AO9: 1637 | AP9: =AO9*AH9 -> 738287 | AQ9: =AN9*AO9 -> 80213
A10: TOYOTA PICHETTI | B10: AMBA | H10: {=TRANSPOSE(Toyota!L2:L25)} -> 7 | I10: 9 | J10: 7 | K10: 13 | L10: 6 | M10: 7 | N10: 8 | O10: 10 | P10: 11 | Q10: 4 | AH10: =SUM(C10:AG10) -> 82 | AI10: =AVERAGE(C10:AG10) -> 8.2 | AJ10: 10 | AK10: =AI10*100/AJ10-100 -> -18 | AL10: 100 | AN10: =AL10-AH10 -> 18 | AO10: 3358 | AP10: =AO10*AH10 -> 275356 | AQ10: =AN10*AO10 -> 60444
AH11: =SUM(AH8:AH10) -> 858 | AI11: =AVERAGE(AI8:AI10) -> 19.351389 | AJ11: =AVERAGE(AJ8:AJ10) -> 20 | AL11: =SUM(AL3:AL10) -> 1420 | AO11: =AVERAGE(AO8:AO10) -> 1989.3333 | AP11: =SUM(AP8:AP10) -> 1329868 | AQ11: =SUM(AQ8:AQ10) -> 213632
A12: 45809
A13: CLIENTE | B13: ZONA | C13: 1 | D13: 2 | E13: 3 | F13: 4 | G13: 5 | H13: 6 | I13: 7 | J13: 8 | K13: 9 | L13: 10 | M13: 11 | N13: 12 | O13: 13 | P13: 14 | Q13: 15 | R13: 16 | S13: 17 | T13: 18 | U13: 19 | V13: 20 | W13: 21 | X13: 22 | Y13: 23 | Z13: 24 | AA13: 25 | AB13: 26 | AC13: 27 | AD13: 28 | AE13: 29 | AF13: 30 | AG13: 31 | AH13: Enviados | AI13: Entregados por dia | AJ13: Por dia | AK13: % Desvio | AL13: Datos pedidos | AN13: Faltantes a enviar | AO13: CPL | AP13: INVERSION REALIZADA | AQ13: INVERSION PENDIENTE
A14: PEUGEOT ALBENS | B14: PAIS | H14: {=TRANSPOSE(Peugeot!L2:L26)} -> 15 | I14: 2 | J14: 4 | K14: 12 | L14: 1 | M14: 4 | N14: 1 | O14: 14 | P14: 10 | Q14: 8 | R14: 15 | S14: 19 | T14: 34 | U14: 26 | V14: 37 | W14: 44 | X14: 59 | Y14: 42 | Z14: 45 | AA14: 57 | AB14: 53 | AC14: 34 | AD14: 29 | AE14: 6 | AF14: 15 | AH14: =SUM(C14:AG14) -> 586 | AI14: =AVERAGE(H14:AF14) -> 23.44 | AJ14: 20 | AK14: =AI14*100/AJ14-100 -> 17.2 | AL14: 550 | AN14: =AL14-AH14 -> -36 | AO14: 1353 | AP14: =AL14*AO14 -> 744150 | AQ14: =AN14*AO14 -> -48708
A15: FIAT AUTOS DEL SOL | B15: AMBA | O15: {=TRANSPOSE(Fiat!L2:L19)} -> 1 | P15: 2 | Q15: 3 | R15: 7 | S15: 7 | T15: 23 | U15: 30 | V15: 23 | W15: 25 | X15: 43 | Y15: 34 | Z15: 38 | AA15: 50 | AB15: 58 | AC15: 45 | AD15: 39 | AE15: 9 | AF15: 16 | AH15: =SUM(C15:AG15) -> 453 | AI15: =AVERAGE(H15:AF15) -> 25.166667 | AJ15: 30 | AK15: =AI15*100/AJ15-100 -> -16.111111 | AL15: 500 | AN15: =AL15-AH15 -> 47 | AO15: 2072 | AP15: =AL15*AO15 -> 1036000 | AQ15: =AN15*AO15 -> 97384
AH16: =SUM(AH14:AH15) -> 1039 | AI16: =AVERAGE(AI13:AI15) -> 24.303333 | AJ16: =AVERAGE(AJ13:AJ15) -> 25 | AL16: =SUM(AL13:AL15) -> 1050 | AO16: =AVERAGE(AO13:AO15) -> 1712.5 | AP16: =SUM(AP13:AP15) -> 1780150 | AQ16: =SUM(AQ13:AQ15) -> 48676

Sheet Dashboard
A1: 45839
A2: CLIENTE | B2: CAMPAÑA | C2: ZONA | D2: 1 | E2: 2 | F2: 3 | G2: 4 | H2: 5 | I2: 6 | J2: 7 | K2: 8 | L2: 9 | M2: 10 | N2: 11 | O2: 12 | P2: 13 | Q2: 14 | R2: 15 | S2: 16 | T2: 17 | U2: 18 | V2: 19 | W2: 20 | X2: 21 | Y2: 22 | Z2: 23 | AA2: 24 | AB2: 25 | AC2: 26 | AD2: 27 | AE2: 28 | AF2: 29 | AG2: 30 | AH2: 31 | AI2: Enviados | AJ2: Entregados por dia | AK2: Pedidos Por dia | AL2: % Desvio | AM2: Datos pedidos 1 | AN2: Faltantes a enviar | AO2: CPL | AP2: INVERSION REALIZADA | AQ2: INVERSION PENDIENTE | AR2: INVERSION TOTAL | AS2: INVERSION TOTAL PENDIENTE
A3: A | B3: 1 | C3: NACIONAL | AM3: 100
A4: A | B4: 2 | C4: NACIONAL | AK4: 25 | AM4: 100
A5: B | B5: 1 | C5: AMBA | AJ5: 5 | AK5: 10 | AL5: =AJ5*100/AK5-100 -> -50 | AM5: 20 | AN5: =AM5-AI5 -> 20 | AO5: 2000 | AP5: =AO5*AN5 -> 40000 | AQ5: =AN5*AO5 -> 40000
A6: CLIENTE | B6: 1 | C6: CORDOBA | Q6: {=TRANSPOSE(Renault!L22:L39)} | AI6: 80 | AJ6: 5 | AK6: 20 | AL6: =AJ6*100/AK6-100 -> -75 | AM6: 100 | AN6: =AM6-AI6 -> 20 | AO6: 1000 | AP6: =AO6*AN6 -> 20000 | AQ6: =AN6*AO6 -> 20000 | AR6: =AP5+AP6 -> 60000 | AS6: =SUM(AQ5+AQ6) -> 60000
A9: Explicacion:
A10: Cliente: Nombre del cliente
A11: Campaña: numero de campaña mensual
A12: Zona: region publicitaria
A13: Dias: del 1 al 31 - se requiere contabilizar los leads diarios enviados por cliente.
A14: Enviados - este dato es tomado de planilla de cantida de leads recolectados
A15: Enviados por dia: Promedio de enviados de todo el mes
A16: Pedidos por dia: numero fijo - lo colocamos nosotros manualmente
A17: % Desvio: Pedidos por dia / Entregados por dia
A18: Datos pedidos: es la cantidad total pedida por cliente - dato manual
A19: CPL: coste por resultado - en lo posible extraerlo de meta ads. sino podems dejarlo manualmente por ahora
A20: Faltantes a enviar: Pedidos - Enviados
... A25: Promedio entregados por dia

Sheet Peugeot
A1: Fecha | B1: Nombre | C1: Telefono | D1: Localidad | E1: Modelo | F1: Horario / Comentarios | G1: ORIGEN | H1: LOCALIZACION | I1: CLIENTE | J1: Formula 1 | K1: Formula 2 | L1: Conteo de leads | M1: Fecha | N1: TOTAL LEADS
A2: 2025-06-06T12:27:03-03:00 | B2: Sin Trabajo | C2: 5491126093351 | D2: Capital | E2: 2008 | F2: Medio dia | G2: Whatsapp | H2: Pais | I2: Albens | J2: {=IF(A2:A1911="", "", DATE(LEFT(A2:A1911,4)*1, MID(A2:A1911,6,2)*1, MID(A2:A1911,9,2)*1))} -> 45814 | K2: {=UNIQUE(J2:J1911)} -> 45814 | L2: {=IF(K2:K1911="", "", COUNTIF(J2:J1911, K2:K1911))} -> 15 | M2: {=IF(K2:K1911="", "", TEXT(K2:K1911, "dd/mm/yyyy"))} -> 06/06/2025 | N2: =SUM(L2:L1911) -> 911
A3: 2025-06-06T13:17:02-03:00 | B3: Fofito | C3: 5493521408603 | D3: Dean Funes provincia de Córdoba | E3: Quisiera más info de financiaciones de Peugeot 0km | F3: Tres | G3: Whatsapp | H3: Pais | I3: Albens | J3: 45814 | K3: 45815 | L3: 2 | M3: 07/06/2025
A4: 2025-06-06T15:50:16-03:00 | B4: Monty | C4: 5493885395195 | D4: Jujuy | E4: Parnet | F4: Ahora | G4: Whatsapp | H4: Pais | I4: Albens | J4: 45814 | K4: 45816 | L4: 4 | M4: 08/06/2025
A5: 2025-06-06T15:05:42-03:00 | B5: Eduardo Cejas | C5: 5493516430233 | D5: interior | E5: 208 | F5: llamar por la tarde | G5: Whatsapp | H5: Pais | I5: Albens | J5: 45814 | K5: 45817 | L5: 12 | M5: 09/06/2025
A6: 2025-06-06T17:38:29-03:00 | B6: Ricardo Mercao Villarroel | C6: 5491158362237 | D6: interior | E6: Hola si me interesa la camioneta partner financiado en cuotas cuanto serian las cuotas x mes | F6: llamar por la tarde | G6: Whatsapp | H6: Pais | I6: Albens | J6: 45814 | K6: 45818 | L6: 1 | M6: 10/06/2025
A7: 2025-06-06T18:01:25-03:00 | B7: Victor Aquino | C7: 5493482575346 | D7: Las toscas provincia de Santa Fe. | E7: Me interesa partner. | F7: Por la mañana. | G7: Whatsapp | H7: Pais | I7: Albens | J7: 45814 | K7: 45819 | L7: 4 | M7: 11/06/2025
A8: 2025-06-06T19:49:26-03:00 | B8: Gabriel | C8: 5493434466369 | D8: Parana entre rios | E8: Parnert | F8: Dale de tarde. Después de las 17 hs | G8: Whatsapp | H8: Pais | I8: Albens | J8: 45814 | K8: 45820 | L8: 1 | M8: 12/06/2025
A9: 2025-06-06T18:54:48-03:00 | B9: Armando.C | C9: 5491137562218 | D9: interior | E9: 208 | F9: llamar por la tarde | G9: Whatsapp | H9: Pais | I9: Albens | J9: 45814 | K9: 45821 | L9: 14 | M9: 13/06/2025
A10: 2025-06-06T20:23:49-03:00 | B10: Javier Gimenez | C10: 5493644677677 | D10: Sáenz peña chaco | E10: Partner | F10: Orario comercial | G10: Whatsapp | H10: Pais | I10: Albens | J10: 45814 | K10: 45822 | L10: 10 | M10: 14/06/2025
A11: 2025-06-06T19:28:41-03:00 | B11: Jose Rivarola | C11: 5492657619845 | D11: De donde son | E11: Partner | F11: llamar por la tarde | G11: Whatsapp | H11: Pais | I11: Albens | J11: 45814 | K11: 45823 | L11: 8 | M11: 15/06/2025
A12: 2025-06-06T20:07:17-03:00 | B12: Kems Calle | C12: 5491161174239 | D12: interior | E12: 208 | F12: llamar por la tarde | G12: Whatsapp | H12: Pais | I12: Albens | J12: 45814 | K12: 45824 | L12: 15 | M12: 16/06/2025
A13: 2025-06-06T20:23:21-03:00 | B13: Osvaldo | C13: 5493858443004 | D13: interior | E13: 208 | F13: llamar por la tarde | G13: Whatsapp | H13: Pais | I13: Albens | J13: 45814 | K13: 45825 | L13: 19 | M13: 17/06/2025
A14: 2025-06-06T20:11:33-03:00 | B14: Marbel Jurado | C14: 5491157121099 | D14: interior | E14: Parner patagonia hdi | F14: llamar por la tarde | G14: Whatsapp | H14: Pais | I14: Albens | J14: 45814 | K14: 45826 | L14: 34 | M14: 18/06/2025
A15: 2025-06-06T21:59:21-03:00 | B15: Miguel Angel Piergiacomi | C15: 5492344402095 | D15: interior | E15: partner te queda patagonica | F15: llamar por la tarde | G15: Whatsapp | H15: Pais | I15: Albens | J15: 45814 | K15: 45827 | L15: 26 | M15: 19/06/2025
A16: 2025-06-06T22:05:10-03:00 | B16: Armando.C | C16: 5491137562218 | D16: interior | E16: Partner | F16: llamar por la tarde | G16: Whatsapp | H16: Pais | I16: Albens | J16: 45814 | K16: 45828 | L16: 37 | M16: 20/06/2025
A17: 2025-06-07T06:15:16-03:00 | B17: ROJITAS X SIEMPRE | C17: 5492996053450 | D17: interior | E17: 208 | F17: llamar por la tarde | G17: Whatsapp | H17: Pais | I17: Albens | J17: 45815 | K17: 45829 | L17: 44 | M17: 21/06/2025
A18: 2025-06-07T06:59:49-03:00 | B18: Oscar Gonzalez | C18: 5491157289470 | D18: interior | E18: Partner hdi vtc plus, 1.6 patagonica . | F18: llamar por la tarde | G18: Whatsapp | H18: Pais | I18: Albens | J18: 45815 | K18: 45830 | L18: 59 | M18: 22/06/2025
A19: 2025-06-08T23:19:57-03:00 | B19: eduar | C19: 5491167053821 | D19: La tablada | E19: Partner | F19: Mañana a la mañana | G19: Whatsapp | H19: Pais | I19: Albens | J19: 45816 | K19: 45831 | L19: 42 | M19: 23/06/2025
A20: 2025-06-08T23:22:38-03:00 | B20: Sergio Avalos | C20: 5491139190970 | D20: Moreno | E20: Partner | F20: 0.79166667 | G20: Whatsapp | H20: Pais | I20: Albens | J20: 45816 | K20: 45832 | L20: 45 | M20: 24/06/2025
A21: 2025-06-08T23:10:03-03:00 | B21: Javier Micucci | C21: 5492984647810 | D21: Río negro | E21: Partner | F21: llamar por la tarde | G21: Whatsapp | H21: Pais | I21: Albens | J21: 45816 | K21: 45833 | L21: 57 | M21: 25/06/2025
A22: 2025-06-08T23:12:18-03:00 | B22: CRISTIAN | C22: 5492612448795 | D22: Mendoza | E22: Partner patagonia | F22: llamar por la tarde | G22: Whatsapp | H22: Pais | I22: Albens | J22: 45816 | K22: 45834 | L22: 53 | M22: 26/06/2025
A23: 2025-06-09T09:00:24-03:00 | B23: Cutty | C23: 5493794291983 | D23: interior | E23: 208 | F23: llamar por la tarde | G23: Whatsapp | H23: Pais | I23: Albens | J23: 45817 | K23: 45835 | L23: 34 | M23: 27/06/2025
A24: 2025-06-09T16:58:22-03:00 | B24: Miguel Alfonso | C24: 5492234220500 | D24: Necesito imágenes y precio y saber donde esta para verla | E24: Me interesa la Patagonia de la imagen | F24: Mar del Plata, Provincia de Buenos Aires | G24: Whatsapp | H24: Pais | I24: Albens | J24: 45817 | K24: 45836 | L24: 29 | M24: 28/06/2025
A25: 2025-06-09T17:08:53-03:00 | B25: luisalberto | C25: 5493884726857 | D25: Jujuy | E25: Partner | F25: En la tarde estoy más libre | G25: Whatsapp | H25: Pais | I25: Albens | J25: 45817 | K25: 45837 | L25: 6 | M25: 29/06/2025
A26: 2025-06-09T19:04:56-03:00 | B26: German Mendez fernandez | C26: 5493876858786 | D26: interior | E26: 208 | F26: llamar por la tarde | G26: Whatsapp | H26: Pais | I26: Albens | J26: 45817 | K26: 45838 | L26: 15 | M26: 30/06/2025
A27: 2025-06-09T20:01:37-03:00 | B27: Juan Orlando Ruiz | C27: 5493865645090 | D27: Tucumán concepción | E27: Eso está bien | F27: Alas 12 | G27: Whatsapp | H27: Pais | I27: Albens | J27: 45817 | K27: 45839 | L27: 13 | M27: 01/07/2025
A28: 2025-06-09T19:27:33-03:00 | B28: Toti | C28: 5493704681237 | D28: Fsa capital | E28: Patagonia | F28: llamar por la tarde | G28: Whatsapp | H28: Pais | I28: Albens | J28: 45817 | K28: 45840 | L28: 34 | M28: 02/07/2025
A29: 2025-06-09T19:35:04-03:00 | B29: Miguel | C29: 5491122657044 | D29: interior | E29: 208 | F29: llamar por la tarde | G29: Whatsapp | H29: Pais | I29: Albens | J29: 45817 | K29: 45841 | L29: 26 | M29: 03/07/2025
A30: 2025-06-09T20:36:44-03:00 | B30: Adrian | C30: 5492216047542 | D30: Bs as(la plata) | E30: Partner | F30: llamar por la tarde | G30: Whatsapp | H30: Pais | I30: Albens | J30: 45817 | K30: 45842 | L30: 25 | M30: 04/07/2025
A31: 2025-06-09T20:43:34-03:00 | B31: Edgar Alonso | C31: 5491135911706 | D31: interior | E31: De cuanto cuotas estamos hablando | F31: llamar por la tarde | G31: Whatsapp | H31: Pais | I31: Albens | J31: 45817 | K31: 45843 | L31: 17 | M31: 05/07/2025
A32: 2025-06-09T21:50:13-03:00 | B32: Diego | C32: 5491164734259 | D32: Zona norte jcpaz | E32: Partner | F32: Entre las 16 y 16 30 | G32: Whatsapp | H32: Pais | I32: Albens | J32: 45817 | K32: 45844 | L32: 20 | M32: 06/07/2025
A33: 2025-06-09T21:00:57-03:00 | B33: Víctor | C33: 5493704585688 | D33: interior | E33: 208 | F33: llamar por la tarde | G33: Whatsapp | H33: Pais | I33: Albens | J33: 45817 | K33: 45845 | L33: 30 | M33: 07/07/2025
A34: 2025-06-09T21:23:38-03:00 | B34: Hugo Nuñez | C34: 5491123084854 | D34: interior | E34: 208 | F34: llamar por la tarde | G34: Whatsapp | H34: Pais | I34: Albens | J34: 45817 | K34: 45846 | L34: 28 | M34: 08/07/2025
A35: 2025-06-10T13:45:31-03:00 | B35: Seba | C35: 5492345441872 | D35: Partner | E35: Me pasa indo | F35: 45802 | G35: Whatsapp | H35: Pais | I35: Albens | J35: 45818 | K35: 45847 | L35: 25 | M35: 09/07/2025
A36: 2025-06-11T00:06:50-03:00 | B36: Leonel Ataliva | C36: 5491171681886 | D36: Buenos Aires Quilmes | E36: Partner | F36: Hola quería dar un anticipo y el resto en cuotas | G36: Whatsapp | H36: Pais | I36: Albens | J36: 45819 | K36: 45848 | L36: 22 | M36: 10/07/2025
A37: 2025-06-11T00:25:06-03:00 | B37: Javier Perez | C37: 5492227510232 | D37: Buenos Aires | E37: Partner | F37: Cualquier horario | G37: Whatsapp | H37: Pais | I37: Albens | J37: 45819 | K37: 45849 | L37: 13 | M37: 11/07/2025
A38: 2025-06-11T00:46:11-03:00 | B38: . | C38: 5493854111727 | D38: Santiago del estero | E38: Partner | F38: 10 am | G38: Whatsapp | H38: Pais | I38: Albens | J38: 45819 | K38: 45850 | L38: 26 | M38: 12/07/2025
A39: 2025-06-11T18:29:45-03:00 | B39: Seba | C39: 5492345441872 | D39: Y no me respondiste | E39: Ya te pregunte | F39: llamar por la tarde | G39: Whatsapp | H39: Pais | I39: Albens | J39: 45819 | K39: 45851 | L39: 25 | M39: 13/07/2025
A40: 2025-06-12T23:22:52-03:00 | B40: Juan Santos Márquez | C40: 5492634558126 | D40: Soy de san Martín | E40: Pagner | F40: 10 de la mañana | G40: Whatsapp | H40: Pais | I40: Albens | J40: 45820 | K40: 45852 | L40: 19 | M40: 14/07/2025
...

Sheet Fiat
A1: Fecha | B1: Nombre | C1: Telefono | D1: Localidad | E1: Modelo | F1: Horario / Comentarios | G1: ORIGEN | H1: LOCALIZACION | I1: CLIENTE | J1: Formula 1 | K1: Formula 2 | L1: Conteo de leads | M1: Fecha | N1: TOTAL LEADS
A2: 2025-06-13T17:07:48-03:00 | B2: Celestina | C2: 5491160502851 | D2: amba | E2: Cómo es la entrega y que requisitos | F2: llamar por la tarde | G2: Whatsapp | H2: Amba | I2: Autos del Sol | J2: {=IF(A2:A2005="", "", DATE(LEFT(A2:A2005,4)*1, MID(A2:A2005,6,2)*1, MID(A2:A2005,9,2)*1))} -> 45821 | K2: {=UNIQUE(J2:J2005)} -> 45821 | L2: {=IF(K2:K2005="", "", COUNTIF(J2:J2005, K2:K2005))} -> 1 | M2: {=IF(K2:K2005="", "", TEXT(K2:K2005, "dd/mm/yyyy"))} -> 13/06/2025 | N2: =SUM(L2:L2005) -> 904
A3: 2025-06-14T09:18:36-03:00 | B3: Cristo X Siempre | C3: 5491133727352 | D3: amba | E3: Cronos | F3: llamar por la tarde | G3: Whatsapp | H3: Amba | I3: Autos del Sol | J3: 45822 | K3: 45822 | L3: 2 | M3: 14/06/2025
A4: 2025-06-14T17:00:49-03:00 | B4: HUMBERTO WALTER CINCO | C4: 5491139286350 | D4: En TORTUGUITA | E4: CRONOS | F4: MAÑANA A LAS 10 X FAVOR GRACIAS | G4: Whatsapp | H4: Amba | I4: Autos del Sol | J4: 45822 | K4: 45823 | L4: 3 | M4: 15/06/2025
A5: 2025-06-15T18:58:36-03:00 | B5: More | C5: 5491166899803 | D5: amba | E5: Cronos | F5: llamar por la tarde | G5: Whatsapp | H5: Amba | I5: Autos del Sol | J5: 45823 | K5: 45824 | L5: 7 | M5: 16/06/2025
A6: 2025-06-15T20:21:32-03:00 | B6: Don Lippo | C6: 5491126506666 | D6: Avellaneda | E6: Cronos | F6: Ahora | G6: Whatsapp | H6: Amba | I6: Autos del Sol | J6: 45823 | K6: 45825 | L6: 7 | M6: 17/06/2025
A7: 2025-06-15T20:51:04-03:00 | B7: Gustavo | C7: 5491151372553 | D7: Caba vlla urquiza | E7: Cronos | F7: A paetir 10 de la mañana | G7: Whatsapp | H7: Amba | I7: Autos del Sol | J7: 45823 | K7: 45826 | L7: 23 | M7: 18/06/2025
A8: 2025-06-16T13:03:05-03:00 | B8: marce | C8: 5491138087112 | D8: San Martín | E8: Okey | F8: En cualquier horrio | G8: Whatsapp | H8: Amba | I8: Autos del Sol | J8: 45824 | K8: 45827 | L8: 30 | M8: 19/06/2025
A9: 2025-06-16T14:25:28-03:00 | B9: Marcelo Lizarraga | C9: 5491153388260 | D9: Tristán Suárez | E9: Cronos | F9: X la tarde | G9: Whatsapp | H9: Amba | I9: Autos del Sol | J9: 45824 | K9: 45828 | L9: 23 | M9: 20/06/2025
A10: 2025-06-16T15:48:49-03:00 | B10: Cheke Seoane 👑 | C10: 5491150516448 | D10: Villa Lugano CABA | E10: Cronos | F10: Me gustaría sacar un Fiat para poder trabajar en aplicación | G10: Whatsapp | H10: Amba | I10: Autos del Sol | J10: 45824 | K10: 45829 | L10: 25 | M10: 21/06/2025
A11: 2025-06-16T16:00:37-03:00 | B11: Amanda Villaruel | C11: 5491134757144 | D11: amba | E11: Cronos | F11: llamar por la tarde | G11: Whatsapp | H11: Amba | I11: Autos del Sol | J11: 45824 | K11: 45830 | L11: 43 | M11: 22/06/2025
A12: 2025-06-16T16:04:38-03:00 | B12: Emilio | C12: 5491130269840 | D12: amba | E12: Cronos | F12: llamar por la tarde | G12: Whatsapp | H12: Amba | I12: Autos del Sol | J12: 45824 | K12: 45831 | L12: 34 | M12: 23/06/2025
A13: 2025-06-16T17:27:26-03:00 | B13: Rosa 🌹 | C13: 5491125907500 | D13: Capital flores | E13: Cronos | F13: Por la tarde tipo 3 adelante gracias | G13: Whatsapp | H13: Amba | I13: Autos del Sol | J13: 45824 | K13: 45832 | L13: 38 | M13: 24/06/2025
A14: 2025-06-16T18:43:55-03:00 | B14: Ismael | C14: 5491141754237 | D14: Ok | E14: Necesito un autochico para mi soy jubilado | F14: Yo estoy | G14: Whatsapp | H14: Amba | I14: Autos del Sol | J14: 45824 | K14: 45833 | L14: 50 | M14: 25/06/2025
... A35: 2025-06-18T19:07:28-03:00 | B35: Rolando | C35: 5491134983585 | D35: Caba | E35: Cronos | F35: llamar por la tarde | G35: Whatsapp | H35: Amba | I35: Autos del Sol | J35: 45826 | K35: 45854 | L35: 11 | M35: 16/07/2025
A36: 2025-06-18T20:19:26-03:00 | B36: ⚽ | C36: 5491171296429 | D36: San Miguel | E36: Cronos | F36: Mañana | G36: Whatsapp | H36: Amba | I36: Autos del Sol | J36: 45826
A37: 2025-06-18T20:29:31-03:00 | B37: El Chuky Antoniotti | C37: 5491149145392 | D37: Norte tigre | E37: Crono | F37: De11 a15 | G37: Whatsapp | H37: Amba | I37: Autos del Sol | J37: 45826
A38: 2025-06-18T20:30:00-03:00 | B38: El Tano | C38: 5491140822835 | D38: amba | E38: Cronos | F38: llamar por la tarde | G38: Whatsapp | H38: Amba | I38: Autos del Sol | J38: 45826
A39: 2025-06-18T20:32:13-03:00 | B39: 🌳🛖🌳🌳🔥🏡🔥🌳🌳🏢🌳 | C39: 5491135204129 | D39: amba | E39: Cronos | F39: llamar por la tarde | G39: Whatsapp | H39: Amba | I39: Autos del Sol | J39: 45826
A40: 2025-06-18T21:05:45-03:00 | B40: hugoalfaro258 | C40: 5491137931252 | D40: amba | E40: Cronos | F40: llamar por la tarde | G40: Whatsapp | H40: Amba | I40: Autos del Sol | J40: 45826
A41: 2025-06-18T21:36:24-03:00 | B41: 🫣 | C41: 5491134153064 | D41: amba | E41: Cronos | F41: llamar por la tarde | G41: Whatsapp | H41: Amba | I41: Autos del Sol | J41: 45826
A42: 2025-06-18T21:37:36-03:00 | B42: Carlos | C42: 5491168063570 | D42: amba | E42: Crono | F42: llamar por la tarde | G42: Whatsapp | H42: Amba | I42: Autos del Sol | J42: 45826
A43: 2025-06-18T21:51:54-03:00 | B43: Dario Juarez | C43: 5491154173644 | D43: amba | E43: Cronos | F43: llamar por la tarde | G43: Whatsapp | H43: Amba | I43: Autos del Sol | J43: 45826
A44: 2025-06-18T23:17:25-03:00 | B44: Eduardo | C44: 5491138768606 | D44: amba | E44: Cronos | F44: llamar por la tarde | G44: Whatsapp | H44: Amba | I44: Autos del Sol | J44: 45826
A45: 2025-06-19T01:40:57-03:00 | B45: Sebastian Galeano | C45: 5491122931813 | D45: Bueno... Solo watsap.... Para que me quede todo... Puede ser?? | E45: Hola... Estoy interesado por el Cronos... | F45: A la hora que sea.. pero solo watsap... | G45: Whatsapp | H45: Amba | I45: Autos del Sol | J45: 45827
A46: 2025-06-19T07:45:14-03:00 | B46: Mathias | C46: 59899142385 | D46: Vivo en cápital Liniers | E46: Arco | F46: Al medio día puede ser | G46: Whatsapp | H46: Amba | I46: Autos del Sol | J46: 45827
A47: 2025-06-19T07:20:15-03:00 | B47: Beto | C47: 5491133927052 | D47: amba | E47: Cronos | F47: llamar por la tarde | G47: Whatsapp | H47: Amba | I47: Autos del Sol | J47: 45827
... A231: 2025-06-24T21:50:04-03:00 | B231: Amor del bueno 💙💛💙 | C231: 5491150240171 | D231: En gregorio de Laferrere | E231: Cronos | F231: De 12 a 12:40 o después de las 17 | G231: Whatsapp | H231: Amba | I231: Autos del Sol | J231: 45832
A232: 2025-06-24T22:14:02-03:00 | B232: 3755384888 | C232: 5493755384888 | D232: Soy de lomas de zamora | E232: El más económico | F232: Buenos aire | G232: Whatsapp | H232: Amba | I232: Autos del Sol | J232: 45832
A233: 2025-06-24T21:27:15-03:00 | B233: Tda La Vida LOMAS 🇦🇹⚔️🇦🇹 | C233: 5491125027028 | D233: amba | E233: Cronos | F233: llamar por la tarde | G233: Whatsapp | H233: Amba | I233: Autos del Sol | J233: 45832
A234: 2025-06-24T22:16:44-03:00 | B234: 😕 | C234: 5491149705386 | D234: amba | E234: Cronos | F234: llamar por la tarde | G234: Whatsapp | H234: Amba | I234: Autos del Sol | J234: 45832
A235: 2025-06-24T22:19:41-03:00 | B235: Richard | C235: 5491134618809 | D235: Banfield | E235: Cronos | F235: llamar por la tarde | G235: Whatsapp | H235: Amba | I235: Autos del Sol | J235: 45832
A236: 2025-06-24T22:29:37-03:00 | B236: Mario Campos | C236: 5491154125578 | D236: Pablo nogues | E236: Mobi | F236: llamar por la tarde | G236: Whatsapp | H236: Amba | I236: Autos del Sol | J236: 45832
A237: 2025-06-24T22:57:07-03:00 | B237: Marcelo🤑🤑 | C237: 5491149705779 | D237: amba | E237: Cronos | F237: llamar por la tarde | G237: Whatsapp | H237: Amba | I237: Autos del Sol | J237: 45832
A238: 2025-06-25T00:16:08-03:00 | B238: lautygt32 | C238: 5491128750358 | D238: Gregorio laferrere | E238: Cronos | F238: llamar por la tarde | G238: Whatsapp | H238: Amba | I238: Autos del Sol | J238: 45833
A239: 2025-06-25T01:35:08-03:00 | B239: Bienestar y servicio | C239: 5493872280342 | D239: amba | E239: Cronos | F239: llamar por la tarde | G239: Whatsapp | H239: Amba | I239: Autos del Sol | J239: 45833
A240: 2025-06-25T04:53:28-03:00 | B240: Tortu | C240: 5491165174482 | D240: amba | E240: Cronos | F240: llamar por la tarde | G240: Whatsapp | H240: Amba | I240: Autos del Sol | J240: 45833
A241: 2025-06-25T06:36:12-03:00 | B241: Cecilia Gonzalez | C241: 5491156014016 | D241: amba | E241: Cronos | F241: llamar por la tarde | G241: Whatsapp | H241: Amba | I241: Autos del Sol | J241: 45833
A242: 2025-06-25T11:12:04-03:00 | B242: Lucas Torres | C242: 5491136848993 | D242: Vicente López | E242: El más económico | F242: X wh8 | G242: Whatsapp | H242: Amba | I242: Autos del Sol | J242: 45833
A243: 2025-06-25T11:52:05-03:00 | B243: Eze | C243: 5491131678125 | D243: Laferrere | E243: Otro | F243: Todo el día solo x vía WhatsApp | G243: Whatsapp | H243: Amba | I243: Autos del Sol | J243: 45833
...

Sheet Toyota
A1: Fecha | B1: Nombre | C1: Telefono | D1: Localidad | E1: Modelo | F1: Horario / Comentarios | G1: ORIGEN | H1: LOCALIZACION | I1: CLIENTE | J1: Formula 1 | K1: Formula 2 | L1: Conteo de leads | M1: Fecha | N1: TOTAL LEADS
A2: 2025-07-06T04:00:39-03:00 | B2: markoss👽👽 | C2: 5491161268319 | D2: amba | E2: Yaris | F2: llamar por la tarde | G2: Whatsapp | H2: Amba | I2: Mariano - Pichetti | J2: {=IF(A2:A1821="", "", DATE(LEFT(A2:A1821,4)*1, MID(A2:A1821,6,2)*1, MID(A2:A1821,9,2)*1))} -> 45844 | K2: {=UNIQUE(J2:J1821)} -> 45844 | L2: {=IF(K2:K1821="", "", COUNTIF(J2:J1821, K2:K1821))} -> 7 | M2: {=IF(K2:K1821="", "", TEXT(K2:K1821, "dd/mm/yyyy"))} -> 06/07/2025 | N2: =SUM(L2:L1821) -> 82
A3: 2025-07-06T06:47:07-03:00 | B3: la mejor | C3: 5491158583622 | D3: amba | E3: Corolla | F3: llamar por la tarde | G3: Whatsapp | H3: Amba | I3: Mariano - Pichetti | J3: 45844 | K3: 45845 | L3: 9 | M3: 07/07/2025
A4: 2025-07-06T14:46:02-03:00 | B4: Jorgecarrasco | C4: 5491124928292 | D4: Lomas de Zamora | E4: Yaris o otro 4 puertas | F4: Después de 20 hs | G4: Whatsapp | H4: Amba | I4: Mariano - Pichetti | J4: 45844 | K4: 45846 | L4: 7 | M4: 08/07/2025
A5: 2025-07-06T16:48:28-03:00 | B5: . | C5: 5492213551096 | D5: amba | E5: Corolla | F5: llamar por la tarde | G5: Whatsapp | H5: Amba | I5: Mariano - Pichetti | J5: 45844 | K5: 45847 | L5: 13 | M5: 09/07/2025
A6: 2025-07-06T16:56:36-03:00 | B6: Mario Luque | C6: 5491121907531 | D6: amba | E6: Corolla | F6: llamar por la tarde | G6: Whatsapp | H6: Amba | I6: Mariano - Pichetti | J6: 45844 | K6: 45848 | L6: 6 | M6: 10/07/2025
A7: 2025-07-06T18:10:08-03:00 | B7: Rubén Drago | C7: 5491134706603 | D7: Martinez | E7: Yaris | F7: llamar por la tarde | G7: Whatsapp | H7: Amba | I7: Mariano - Pichetti | J7: 45844 | K7: 45849 | L7: 7 | M7: 11/07/2025
A8: 2025-07-06T23:28:16-03:00 | B8: luis campopiano | C8: 5491127001718 | D8: amba | E8: Corolla | F8: llamar por la tarde | G8: Whatsapp | H8: Amba | I8: Mariano - Pichetti | J8: 45844 | K8: 45850 | L8: 8 | M8: 12/07/2025
A9: 2025-07-07T10:40:33-03:00 | B9: Mar Benve | C9: 5491165286440 | D9: Caba | E9: Yaris | F9: Todo el día | G9: Whatsapp | H9: Amba | I9: Mariano - Pichetti | J9: 45845 | K9: 45851 | L9: 10 | M9: 13/07/2025
A10: 2025-07-07T12:58:09-03:00 | B10: Mi Pepi | C10: 5491168204221 | D10: Retro | E10: Yatis | F10: Tarde | G10: Whatsapp | H10: Amba | I10: Mariano - Pichetti | J10: 45845 | K10: 45852 | L10: 11 | M10: 14/07/2025
A11: 2025-07-07T16:25:03-03:00 | B11: Jesus Ramon Andino | C11: 5493516105567 | D11: Caba. Belgrano | E11: Yaris | F11: Podes ahora ?? | G11: Whatsapp | H11: Amba | I11: Mariano - Pichetti | J11: 45845 | K11: 45853 | L11: 4 | M11: 15/07/2025
A12: 2025-07-07T16:36:32-03:00 | B12: Daniel Rodríguez | C12: 5492267418622 | D12: Madariaga | E12: Hilux | F12: llamar por la tarde | G12: Whatsapp | H12: Amba | I12: Mariano - Pichetti | J12: 45845
A13: 2025-07-07T16:43:58-03:00 | B13: Imgresos Salud mental | C13: 5491139346157 | D13: amba | E13: Corolla | F13: llamar por la tarde | G13: Whatsapp | H13: Amba | I13: Mariano - Pichetti | J13: 45845
A14: 2025-07-07T16:50:01-03:00 | B14: Mi Alma Mi Vida Toda | C14: 5492233120340 | D14: amba | E14: Corolla | F14: llamar por la tarde | G14: Whatsapp | H14: Amba | I14: Mariano - Pichetti | J14: 45845
A15: 2025-07-07T20:03:22-03:00 | B15: Diego | C15: 5491126058598 | D15: Vicecente lopez | E15: Hilux | F15: Ahora | G15: Whatsapp | H15: Amba | I15: Mariano - Pichetti | J15: 45845
A16: 2025-07-07T22:45:28-03:00 | B16: Sebas | C16: 5491161172314 | D16: Pilar | E16: Corolla | F16: 9:00 am | G16: Whatsapp | H16: Amba | I16: Mariano - Pichetti | J16: 45845
A17: 2025-07-07T23:33:47-03:00 | B17: Adrian | C17: 5491123775197 | D17: Zona sur avellaneda | E17: Corolla | F17: Tomando usado de 10 a 14 | G17: Whatsapp | H17: Amba | I17: Mariano - Pichetti | J17: 45845
A18: 2025-07-08T00:35:41-03:00 | B18: Jose Luis Contreras Salu | C18: 5491164273381 | D18: Quilmes | E18: Hilux | F18: Cuando puedas | G18: Whatsapp | H18: Amba | I18: Mariano - Pichetti | J18: 45846
A19: 2025-07-08T00:17:31-03:00 | B19: Leandro Tissoni | C19: 5492355463850 | D19: amba | E19: Corolla | F19: llamar por la tarde | G19: Whatsapp | H19: Amba | I19: Mariano - Pichetti | J19: 45846
A20: 2025-07-08T06:34:30-03:00 | B20: julian flores | C20: 5491155796021 | D20: amba | E20: Corolla | F20: llamar por la tarde | G20: Whatsapp | H20: Amba | I20: Mariano - Pichetti | J20: 45846
A21: 2025-07-08T08:16:32-03:00 | B21: Gaston | C21: 5491127563706 | D21: amba | E21: Corolla | F21: llamar por la tarde | G21: Whatsapp | H21: Amba | I21: Mariano - Pichetti | J21: 45846
A22: 2025-07-08T14:12:17-03:00 | B22: Rolo | C22: 5492233486450 | D22: Mardel plata | E22: Corolla | F22: llamar por la tarde | G22: Whatsapp | H22: Amba | I22: Mariano - Pichetti | J22: 45846
A23: 2025-07-08T15:02:19-03:00 | B23: Fabi | C23: 5493777404671 | D23: amba | E23: Corolla | F23: llamar por la tarde | G23: Whatsapp | H23: Amba | I23: Mariano - Pichetti | J23: 45846
... A25: 2025-07-09T09:35:41-03:00 | B25: Domingo | C25: 5491157255097 | D25: Ok | E25: Corolla | F25: Se puede contactar a partir de las 9 hrs en adelante | G25: Whatsapp | H25: Amba | I25: Mariano - Pichetti | J25: 45847
A26: 2025-07-09T10:17:39-03:00 | B26: Claudio | C26: 5491162912280 | D26: Merlo | E26: Corolla | F26: 1162912280 | G26: Whatsapp | H26: Amba | I26: Mariano - Pichetti | J26: 45847
A27: 2025-07-09T09:44:45-03:00 | B27: Jose | C27: 5491127999846 | D27: amba | E27: Corolla | F27: llamar por la tarde | G27: Whatsapp | H27: Amba | I27: Mariano - Pichetti | J27: 45847
A28: 2025-07-09T11:11:33-03:00 | B28: Patricia Ferrero | C28: 5492342558561 | D28: BRAGADO provincia de Buenos Aires | E28: Corolla | F28: Después de las 16 y 30 hs | G28: Whatsapp | H28: Amba | I28: Mariano - Pichetti | J28: 45847
A29: 2025-07-09T10:50:10-03:00 | B29: ❄️🌸🍋🍊🥭🍪🍬🐬🫵🏾 | C29: 5491136813214 | D29: amba | E29: Corolla | F29: llamar por la tarde | G29: Whatsapp | H29: Amba | I29: Mariano - Pichetti | J29: 45847
A30: 2025-07-09T14:26:03-03:00 | B30: demetriotorales | C30: 5491167031533 | D30: Soy de mariano Acosta partido de Merlo | E30: Hola quétal una Toyota Hilux | F30: Durante por la mañana sin problema | G30: Whatsapp | H30: Amba | I30: Mariano - Pichetti | J30: 45847
A31: 2025-07-09T17:08:43-03:00 | B31: Richi | C31: 5491136413551 | D31: Avellaneda | E31: Corolla | F31: En la tarde | G31: Whatsapp | H31: Amba | I31: Mariano - Pichetti | J31: 45847
A32: 2025-07-09T17:10:17-03:00 | B32: Mario | C32: 5491150103017 | D32: Ramos Mejía | E32: Corolla | F32: Cualquier horario | G32: Whatsapp | H32: Amba | I32: Mariano - Pichetti | J32: 45847
A33: 2025-07-09T18:32:52-03:00 | B33: Gaston | C33: 5491162490000 | D33: Quilmes | E33: Corola | F33: 0.70833333 | G33: Whatsapp | H33: Amba | I33: Mariano - Pichetti | J33: 45847
A34: 2025-07-09T18:22:01-03:00 | B34: Pedro | C34: 5491160012019 | D34: Grandbourg | E34: Hilux | F34: llamar por la tarde | G34: Whatsapp | H34: Amba | I34: Mariano - Pichetti | J34: 45847
A35: 2025-07-09T19:33:04-03:00 | B35: Luciano Valenzuela | C35: 5491151499379 | D35: Pilar | E35: Yaris | F35: Mañana | G35: Whatsapp | H35: Amba | I35: Mariano - Pichetti | J35: 45847
A36: 2025-07-09T22:07:50-03:00 | B36: Naino | C36: 5491157826395 | D36: Sona sur | E36: Corola | F36: llamar por la tarde | G36: Whatsapp | H36: Amba | I36: Mariano - Pichetti | J36: 45847
A37: 2025-07-09T22:32:55-03:00 | B37: Dioni | C37: 5493884719694 | D37: amba | E37: Corolla | F37: llamar por la tarde | G37: Whatsapp | H37: Amba | I37: Mariano - Pichetti | J37: 45847
A38: 2025-07-10T06:36:33-03:00 | B38: Franco | C38: 5491178431076 | D38: Puedo entregar un dinero y el resto en cuotas | E38: Cómo compro una Toyota Hilux | F38: Don Torcuato | G38: Whatsapp | H38: Amba | I38: Mariano - Pichetti | J38: 45848
A39: 2025-07-10T08:50:01-03:00 | B39: Rafael Monzón | C39: 5491134255877 | D39: Vivo en San Miguel buenos aires | E39: Me interesa un Toyota Corolla que precio está, | F39: Si puede ahora o a partir de las 14 horas | G39: Whatsapp | H39: Amba | I39: Mariano - Pichetti | J39: 45848
A40: 2025-07-10T09:57:59-03:00 | B40: Sergio Daniel Solís | C40: 5491162145822 | D40: amba | E40: Hilux | F40: llamar por la tarde | G40: Whatsapp | H40: Amba | I40: Mariano - Pichetti | J40: 45848
A41: 2025-07-10T12:22:02-03:00 | B41: Diego | C41: 5491156472776 | D41: Nuevo | E41: Corola | F41: Quilmes sona sur | G41: Whatsapp | H41: Amba | I41: Mariano - Pichetti | J41: 45848
...

Sheet Chevrolet
A1: Fecha | B1: Nombre | C1: Telefono | D1: Localidad | E1: Modelo | F1: Horario / Comentarios | G1: ORIGEN | H1: LOCALIZACION | I1: CLIENTE | J1: Formula 1 | K1: Formula 2 | L1: Conteo de leads | M1: Fecha | N1: TOTAL LEADS
A2: 2025-07-14T12:02:41-03:00 | B2: 💙🩷💙💙🩷💙 L.L.P.J.B.S | C2: 5492392688243 | D2: Trenque lauquen | E2: El más económico de chevrolet | F2: De 14 a 20hs | G2: Whatsapp | H2: Amba | I2: Chevrolet Italy | J2: {=IF(A2:A1048="", "", DATE(LEFT(A2:A1048,4)*1, MID(A2:A1048,6,2)*1, MID(A2:A1048,9,2)*1))} -> 45852 | K2: {=UNIQUE(J2:J1048)} -> 45852 | L2: {=IF(K2:K1048="", "", COUNTIF(J2:J1048, K2:K1048))} -> 17 | M2: {=IF(K2:K1048="", "", TEXT(K2:K1048, "dd/mm/yyyy"))} -> 14/07/2025 | N2: =SUM(L2:L1856) -> 47
A3: 2025-07-14T12:48:16-03:00 | B3: Luis Romero | C3: 5493625196255 | D3: amba | E3: Hola la montana | F3: llamar por la tarde | G3: Whatsapp | H3: Amba | I3: Chevrolet Italy | J3: 45852 | K3: 45853 | L3: 28 | M3: 15/07/2025
A4: 2025-07-14T14:40:28-03:00 | B4: Aldo | C4: 5492664661058 | D4: San luis capital | E4: Onix | F4: llamar por la tarde | G4: Whatsapp | H4: Amba | I4: Chevrolet Italy | J4: 45852 | K4: 45854 | L4: 2 | M4: 16/07/2025
A5: 2025-07-14T17:21:08-03:00 | B5: Luciano | C5: 5493515153829 | D5: Cordoba | E5: Onix tracker | F5: Alas 9 de la mañana | G5: Whatsapp | H5: Amba | I5: Chevrolet Italy | J5: 45852
A6: 2025-07-14T17:42:04-03:00 | B6: Jcvd | C6: 5492954653421 | D6: Toay la pampa | E6: Me pasas presio de la Traker cero km | F6: Ahora | G6: Whatsapp | H6: Amba | I6: Chevrolet Italy | J6: 45852
A7: 2025-07-14T17:25:15-03:00 | B7: 🤩cc | C7: 5493754430917 | D7: amba | E7: Onix | F7: llamar por la tarde | G7: Whatsapp | H7: Amba | I7: Chevrolet Italy | J7: 45852
A8: 2025-07-14T17:30:49-03:00 | B8: Moises | C8: 5493757310447 | D8: amba | E8: Onix | F8: llamar por la tarde | G8: Whatsapp | H8: Amba | I8: Chevrolet Italy | J8: 45852
A9: 2025-07-14T18:37:11-03:00 | B9: Ceferino manuel Aragon | C9: 5491150410323 | D9: Soy de san Martín | E9: Tracker | F9: Reciben plan caídos tengo 2 | G9: Whatsapp | H9: Amba | I9: Chevrolet Italy | J9: 45852
A10: 2025-07-14T18:43:24-03:00 | B10: Gregorio Guanco | C10: 5491126867399 | D10: Nos o uno con motor 1.4 y baúl | E10: Sera verdad | F10: llamar por la tarde | G10: Whatsapp | H10: Amba | I10: Chevrolet Italy | J10: 45852
A11: 2025-07-14T18:57:07-03:00 | B11: Mirta Saavedra | C11: 5493704375993 | D11: amba | E11: S10 | F11: llamar por la tarde | G11: Whatsapp | H11: Amba | I11: Chevrolet Italy | J11: 45852
A12: 2025-07-14T20:32:15-03:00 | B12: iriarteruben621 | C12: 5491124032942 | D12: Berazategui | E12: Onix caja automática | F12: Bien. Desde 14 hs en adelante | G12: Whatsapp | H12: Amba | I12: Chevrolet Italy | J12: 45852
A13: 2025-07-14T20:41:58-03:00 | B13: MARTIN RIOS | C13: 5492625525681 | D13: amba | E13: Onix | F13: llamar por la tarde | G13: Whatsapp | H13: Amba | I13: Chevrolet Italy | J13: 45852
A14: 2025-07-14T21:46:14-03:00 | B14: Taller Luis The Hammer | C14: 5493751306611 | D14: En misiones eldorado | E14: ONIX | F14: De 8 a 19 horas | G14: Whatsapp | H14: Amba | I14: Chevrolet Italy | J14: 45852
A15: 2025-07-14T21:18:08-03:00 | B15: Juan abel Argañaraz | C15: 5491139220272 | D15: amba | E15: Hole gente | F15: llamar por la tarde | G15: Whatsapp | H15: Amba | I15: Chevrolet Italy | J15: 45852
A16: 2025-07-14T21:19:46-03:00 | B16: Gabriel Cáceres | C16: 5491162134701 | D16: amba | E16: Onix | F16: llamar por la tarde | G16: Whatsapp | H16: Amba | I16: Chevrolet Italy | J16: 45852
... A48: 2025-07-16T10:15:29-03:00 | B48: Dios es fiel | C48: 5493624772542 | D48: Resistencia chaco | E48: Onix | F48: Si ahora estoy disponible | G48: Whatsapp | H48: Amba | I48: Chevrolet Italy | J48: 45854

Sheet Renault
A1: Fecha | B1: Nombre | C1: Telefono | D1: Localidad | E1: Modelo | F1: Horario / Comentarios | G1: ORIGEN | H1: LOCALIZACION | I1: CLIENTE | J1: Formula 1 | K1: Formula 2 | L1: Conteo de leads | M1: Fecha | N1: TOTAL LEADS
A2: 2025-07-14T16:12:53-03:00 | B2: Hector | C2: 5491140943116 | D2: Caba Soldati | E2: Kangoo combinada gracias | F2: Me gustaría en el local | G2: Whatsapp | H2: Amba | I2: Javier Cagiao | J2: {=IF(A2:A1023="", "", DATE(LEFT(A2:A1023,4)*1, MID(A2:A1023,6,2)*1, MID(A2:A1023,9,2)*1))} -> 45852 | K2: {=UNIQUE(J2:J1023)} -> 45852 | L2: {=IF(K2:K1023="", "", COUNTIF(J2:J1023, K2:K1023))} -> 7 | M2: {=IF(K2:K1023="", "", TEXT(K2:K1023, "dd/mm/yyyy"))} -> 14/07/2025 | N2: =SUM(L2:L1839) -> 20
A3: 2025-07-14T18:04:40-03:00 | B3: 5491158720915 | C3: 5491158720915 | D3: Capital, Monserrat | E3: Kangoo | F3: llamar por la tarde | G3: Whatsapp | H3: Amba | I3: Javier Cagiao | J3: 45852 | K3: 45853 | L3: 12 | M3: 15/07/2025
A4: 2025-07-14T19:21:52-03:00 | B4: Emiliano | C4: 5492645731464 | D4: Rawson san juan | E4: Kangoo | F4: Desd las 18hs en adelante | G4: Whatsapp | H4: Amba | I4: Javier Cagiao | J4: 45852 | K4: 45854 | L4: 1 | M4: 16/07/2025
A5: 2025-07-14T19:15:15-03:00 | B5: Kary | C5: 5491122979759 | D5: Tablada | E5: Kanguo | F5: 14hs | G5: Whatsapp | H5: Amba | I5: Javier Cagiao | J5: 45852
A6: 2025-07-14T20:29:05-03:00 | B6: Lucas | C6: 5491131438895 | D6: amba | E6: Kwid | F6: llamar por la tarde | G6: Whatsapp | H6: Amba | I6: Javier Cagiao | J6: 45852
A7: 2025-07-14T22:49:14-03:00 | B7: Juli.sala | C7: 5491162867075 | D7: Color Roja | E7: La kardian | F7: Tipo 14 hs | G7: Whatsapp | H7: Amba | I7: Javier Cagiao | J7: 45852
A8: 2025-07-14T22:20:30-03:00 | B8: Oscar | C8: 5491121736343 | D8: amba | E8: Kwid | F8: llamar por la tarde | G8: Whatsapp | H8: Amba | I8: Javier Cagiao | J8: 45852
A9: 2025-07-15T05:33:02-03:00 | B9: Jose | C9: 5491122666749 | D9: amba | E9: Kwid | F9: llamar por la tarde | G9: Whatsapp | H9: Amba | I9: Javier Cagiao | J9: 45853
A10: 2025-07-15T07:42:51-03:00 | B10: Miguel | C10: 5491162763071 | D10: Ciudadela | E10: Kangoo | F10: Después delas 6 pm | G10: Whatsapp | H10: Amba | I10: Javier Cagiao | J10: 45853
A11: 2025-07-15T07:57:27-03:00 | B11: Skyhawk | C11: 5491152606837 | D11: Okey | E11: Él auto kwid | F11: En el dia ahora | G11: Whatsapp | H11: Amba | I11: Javier Cagiao | J11: 45853
A12: 2025-07-15T08:20:13-03:00 | B12: Henrry Cardozo | C12: 5493875513462 | D12: Buenos aires capital | E12: Kangoo | F12: En la mañana | G12: Whatsapp | H12: Amba | I12: Javier Cagiao | J12: 45853
A13: 2025-07-15T08:41:17-03:00 | B13: ❤️🥰 | C13: 5491158335393 | D13: Ok | E13: Kangoo | F13: Kangoo 5 asientos | G13: Whatsapp | H13: Amba | I13: Javier Cagiao | J13: 45853
A14: 2025-07-15T10:11:58-03:00 | B14: Damian Carrasco | C14: 5491168385245 | D14: San Martín | E14: Kangoo | F14: 0.75 | G14: Whatsapp | H14: Amba | I14: Javier Cagiao | J14: 45853
A15: 2025-07-15T13:04:23-03:00 | B15: Ricky | C15: 5491161700009 | D15: amba | E15: Kangoo | F15: llamar por la tarde | G15: Whatsapp | H15: Amba | I15: Javier Cagiao | J15: 45853
A16: 2025-07-15T15:07:01-03:00 | B16: Skyhawk | C16: 5491152606837 | D16: Virrey del pino | E16: Kwid | F16: Ahora | G16: Whatsapp | H16: Amba | I16: Javier Cagiao | J16: 45853
A17: 2025-07-15T18:58:33-03:00 | B17: Arturo | C17: 5491158642404 | D17: Exaltacion de la cruz | E17: Kangoo | F17: De 9 a 15 | G17: Whatsapp | H17: Amba | I17: Javier Cagiao | J17: 45853
A18: 2025-07-15T19:24:31-03:00 | B18: Raquel Tarantelli | C18: 5491136051477 | D18: Lanús oeste | E18: Kangoo | F18: llamar por la tarde | G18: Whatsapp | H18: Amba | I18: Javier Cagiao | J18: 45853
A19: 2025-07-15T23:17:07-03:00 | B19: ADMINISTRACION | C19: 59175244900 | D19: amba | E19: Kwid | F19: llamar por la tarde | G19: Whatsapp | H19: Amba | I19: Javier Cagiao | J19: 45853
A20: 2025-07-15T22:36:40-03:00 | B20: Brian | C20: 5491125331131 | D20: amba | E20: Kangoo | F20: llamar por la tarde | G20: Whatsapp | H20: Amba | I20: Javier Cagiao | J20: 45853
A21: 2025-07-16T01:08:31-03:00 | B21: GO CLICK! | C21: 5491126328889 | D21: Don Torcuato | E21: Kangoo | F21: A partir de las 10 | G21: Whatsapp | H21: Amba | I21: Javier Cagiao | J21: 45854

Sheet Citroen
A1: Fecha | B1: Nombre | C1: Telefono | D1: Localidad | E1: Modelo | F1: Horario / Comentarios | G1: ORIGEN | H1: LOCALIZACION | I1: CLIENTE | J1: Formula 1 | K1: Formula 2 | L1: Conteo de leads | M1: Fecha | N1: TOTAL LEADS
